ERROR:app:Exception on / [GET]
Traceback (most recent call last):
  File "/Library/Frameworks/Python.framework/Versions/3.10/lib/python3.10/site-packages/flask/app.py", line 2077, in wsgi_app
    response = self.full_dispatch_request()
  File "/Library/Frameworks/Python.framework/Versions/3.10/lib/python3.10/site-packages/flask/app.py", line 1525, in full_dispatch_request
    rv = self.handle_user_exception(e)
  File "/Library/Frameworks/Python.framework/Versions/3.10/lib/python3.10/site-packages/flask/app.py", line 1523, in full_dispatch_request
    rv = self.dispatch_request()
  File "/Library/Frameworks/Python.framework/Versions/3.10/lib/python3.10/site-packages/flask/app.py", line 1509, in dispatch_request
    return self.ensure_sync(self.view_functions[rule.endpoint])(**req.view_args)
  File "/Users/emmanuelpinca/Documents/2022-sem1/COMP90024/assignments/2/COMP90024A2/app/app.py", line 254, in index
    scatter, freq, corr, = get_correlation(twitter_data, pollution_data)
  File "/Users/emmanuelpinca/Documents/2022-sem1/COMP90024/assignments/2/COMP90024A2/app/app.py", line 205, in get_correlation
    freq = correlationData.plot(kind='bar',x='%',y='counts_y',color='red')
  File "/Library/Frameworks/Python.framework/Versions/3.10/lib/python3.10/site-packages/pandas/plotting/_core.py", line 972, in __call__
    return plot_backend.plot(data, kind=kind, **kwargs)
  File "/Library/Frameworks/Python.framework/Versions/3.10/lib/python3.10/site-packages/pandas/plotting/_matplotlib/__init__.py", line 71, in plot
    plot_obj.generate()
  File "/Library/Frameworks/Python.framework/Versions/3.10/lib/python3.10/site-packages/pandas/plotting/_matplotlib/core.py", line 336, in generate
    self._post_plot_logic(ax, self.data)
  File "/Library/Frameworks/Python.framework/Versions/3.10/lib/python3.10/site-packages/pandas/plotting/_matplotlib/core.py", line 1577, in _post_plot_logic
    s_edge = self.ax_pos[0] - 0.25 + self.lim_offset
IndexError: index 0 is out of bounds for axis 0 with size 0
ERROR:app:Exception on / [GET]
Traceback (most recent call last):
  File "/Library/Frameworks/Python.framework/Versions/3.10/lib/python3.10/site-packages/flask/app.py", line 2077, in wsgi_app
    response = self.full_dispatch_request()
  File "/Library/Frameworks/Python.framework/Versions/3.10/lib/python3.10/site-packages/flask/app.py", line 1525, in full_dispatch_request
    rv = self.handle_user_exception(e)
  File "/Library/Frameworks/Python.framework/Versions/3.10/lib/python3.10/site-packages/flask/app.py", line 1523, in full_dispatch_request
    rv = self.dispatch_request()
  File "/Library/Frameworks/Python.framework/Versions/3.10/lib/python3.10/site-packages/flask/app.py", line 1509, in dispatch_request
    return self.ensure_sync(self.view_functions[rule.endpoint])(**req.view_args)
  File "/Users/emmanuelpinca/Documents/2022-sem1/COMP90024/assignments/2/COMP90024A2/app/app.py", line 254, in index
    scatter, freq, corr, = get_correlation(twitter_data, pollution_data)
  File "/Users/emmanuelpinca/Documents/2022-sem1/COMP90024/assignments/2/COMP90024A2/app/app.py", line 205, in get_correlation
    freq = correlationData.plot(kind='bar',x='%',y='counts_y',color='red')
  File "/Library/Frameworks/Python.framework/Versions/3.10/lib/python3.10/site-packages/pandas/plotting/_core.py", line 972, in __call__
    return plot_backend.plot(data, kind=kind, **kwargs)
  File "/Library/Frameworks/Python.framework/Versions/3.10/lib/python3.10/site-packages/pandas/plotting/_matplotlib/__init__.py", line 71, in plot
    plot_obj.generate()
  File "/Library/Frameworks/Python.framework/Versions/3.10/lib/python3.10/site-packages/pandas/plotting/_matplotlib/core.py", line 336, in generate
    self._post_plot_logic(ax, self.data)
  File "/Library/Frameworks/Python.framework/Versions/3.10/lib/python3.10/site-packages/pandas/plotting/_matplotlib/core.py", line 1577, in _post_plot_logic
    s_edge = self.ax_pos[0] - 0.25 + self.lim_offset
IndexError: index 0 is out of bounds for axis 0 with size 0
ERROR:app:Exception on / [GET]
Traceback (most recent call last):
  File "/Library/Frameworks/Python.framework/Versions/3.10/lib/python3.10/site-packages/flask/app.py", line 2077, in wsgi_app
    response = self.full_dispatch_request()
  File "/Library/Frameworks/Python.framework/Versions/3.10/lib/python3.10/site-packages/flask/app.py", line 1525, in full_dispatch_request
    rv = self.handle_user_exception(e)
  File "/Library/Frameworks/Python.framework/Versions/3.10/lib/python3.10/site-packages/flask/app.py", line 1523, in full_dispatch_request
    rv = self.dispatch_request()
  File "/Library/Frameworks/Python.framework/Versions/3.10/lib/python3.10/site-packages/flask/app.py", line 1509, in dispatch_request
    return self.ensure_sync(self.view_functions[rule.endpoint])(**req.view_args)
  File "/Users/emmanuelpinca/Documents/2022-sem1/COMP90024/assignments/2/COMP90024A2/app/app.py", line 254, in index
    scatter, freq, corr, = get_correlation(twitter_data, pollution_data)
  File "/Users/emmanuelpinca/Documents/2022-sem1/COMP90024/assignments/2/COMP90024A2/app/app.py", line 205, in get_correlation
    freq = correlationData.plot(kind='bar',x='%',y='counts_y',color='red')
  File "/Library/Frameworks/Python.framework/Versions/3.10/lib/python3.10/site-packages/pandas/plotting/_core.py", line 972, in __call__
    return plot_backend.plot(data, kind=kind, **kwargs)
  File "/Library/Frameworks/Python.framework/Versions/3.10/lib/python3.10/site-packages/pandas/plotting/_matplotlib/__init__.py", line 71, in plot
    plot_obj.generate()
  File "/Library/Frameworks/Python.framework/Versions/3.10/lib/python3.10/site-packages/pandas/plotting/_matplotlib/core.py", line 336, in generate
    self._post_plot_logic(ax, self.data)
  File "/Library/Frameworks/Python.framework/Versions/3.10/lib/python3.10/site-packages/pandas/plotting/_matplotlib/core.py", line 1577, in _post_plot_logic
    s_edge = self.ax_pos[0] - 0.25 + self.lim_offset
IndexError: index 0 is out of bounds for axis 0 with size 0
Traceback (most recent call last):
  File "/Users/emmanuelpinca/Documents/2022-sem1/COMP90024/assignments/2/COMP90024A2/app/app.py", line 277, in <module>
    serve(app, host="127.0.0.1", port=8080) # use serve for production development
  File "/Library/Frameworks/Python.framework/Versions/3.10/lib/python3.10/site-packages/waitress/__init__.py", line 13, in serve
    server = _server(app, **kw)
  File "/Library/Frameworks/Python.framework/Versions/3.10/lib/python3.10/site-packages/waitress/server.py", line 78, in create_server
    last_serv = TcpWSGIServer(
  File "/Library/Frameworks/Python.framework/Versions/3.10/lib/python3.10/site-packages/waitress/server.py", line 244, in __init__
    self.bind_server_socket()
  File "/Library/Frameworks/Python.framework/Versions/3.10/lib/python3.10/site-packages/waitress/server.py", line 361, in bind_server_socket
    self.bind(sockaddr)
  File "/Library/Frameworks/Python.framework/Versions/3.10/lib/python3.10/site-packages/waitress/wasyncore.py", line 396, in bind
    return self.socket.bind(addr)
OSError: [Errno 48] Address already in use
ERROR:app:Exception on / [GET]
Traceback (most recent call last):
  File "/Library/Frameworks/Python.framework/Versions/3.10/lib/python3.10/site-packages/flask/app.py", line 2077, in wsgi_app
    response = self.full_dispatch_request()
  File "/Library/Frameworks/Python.framework/Versions/3.10/lib/python3.10/site-packages/flask/app.py", line 1525, in full_dispatch_request
    rv = self.handle_user_exception(e)
  File "/Library/Frameworks/Python.framework/Versions/3.10/lib/python3.10/site-packages/flask/app.py", line 1523, in full_dispatch_request
    rv = self.dispatch_request()
  File "/Library/Frameworks/Python.framework/Versions/3.10/lib/python3.10/site-packages/flask/app.py", line 1509, in dispatch_request
    return self.ensure_sync(self.view_functions[rule.endpoint])(**req.view_args)
  File "/Users/emmanuelpinca/Documents/2022-sem1/COMP90024/assignments/2/COMP90024A2/app/app.py", line 254, in index
    scatter, freq, corr, = get_correlation(twitter_data, pollution_data)
  File "/Users/emmanuelpinca/Documents/2022-sem1/COMP90024/assignments/2/COMP90024A2/app/app.py", line 205, in get_correlation
    freq = correlationData.plot(kind='bar',x='%',y='counts_y',color='red')
  File "/Library/Frameworks/Python.framework/Versions/3.10/lib/python3.10/site-packages/pandas/plotting/_core.py", line 972, in __call__
    return plot_backend.plot(data, kind=kind, **kwargs)
  File "/Library/Frameworks/Python.framework/Versions/3.10/lib/python3.10/site-packages/pandas/plotting/_matplotlib/__init__.py", line 71, in plot
    plot_obj.generate()
  File "/Library/Frameworks/Python.framework/Versions/3.10/lib/python3.10/site-packages/pandas/plotting/_matplotlib/core.py", line 336, in generate
    self._post_plot_logic(ax, self.data)
  File "/Library/Frameworks/Python.framework/Versions/3.10/lib/python3.10/site-packages/pandas/plotting/_matplotlib/core.py", line 1577, in _post_plot_logic
    s_edge = self.ax_pos[0] - 0.25 + self.lim_offset
IndexError: index 0 is out of bounds for axis 0 with size 0
ERROR:app:Exception on / [GET]
Traceback (most recent call last):
  File "/Library/Frameworks/Python.framework/Versions/3.10/lib/python3.10/site-packages/flask/app.py", line 2077, in wsgi_app
    response = self.full_dispatch_request()
  File "/Library/Frameworks/Python.framework/Versions/3.10/lib/python3.10/site-packages/flask/app.py", line 1525, in full_dispatch_request
    rv = self.handle_user_exception(e)
  File "/Library/Frameworks/Python.framework/Versions/3.10/lib/python3.10/site-packages/flask/app.py", line 1523, in full_dispatch_request
    rv = self.dispatch_request()
  File "/Library/Frameworks/Python.framework/Versions/3.10/lib/python3.10/site-packages/flask/app.py", line 1509, in dispatch_request
    return self.ensure_sync(self.view_functions[rule.endpoint])(**req.view_args)
  File "/Users/emmanuelpinca/Documents/2022-sem1/COMP90024/assignments/2/COMP90024A2/app/app.py", line 254, in index
    scatter, freq, corr, = get_correlation(twitter_data, pollution_data)
  File "/Users/emmanuelpinca/Documents/2022-sem1/COMP90024/assignments/2/COMP90024A2/app/app.py", line 205, in get_correlation
    freq = correlationData.plot(kind='bar',x='%',y='counts_y',color='red')
  File "/Library/Frameworks/Python.framework/Versions/3.10/lib/python3.10/site-packages/pandas/plotting/_core.py", line 972, in __call__
    return plot_backend.plot(data, kind=kind, **kwargs)
  File "/Library/Frameworks/Python.framework/Versions/3.10/lib/python3.10/site-packages/pandas/plotting/_matplotlib/__init__.py", line 71, in plot
    plot_obj.generate()
  File "/Library/Frameworks/Python.framework/Versions/3.10/lib/python3.10/site-packages/pandas/plotting/_matplotlib/core.py", line 336, in generate
    self._post_plot_logic(ax, self.data)
  File "/Library/Frameworks/Python.framework/Versions/3.10/lib/python3.10/site-packages/pandas/plotting/_matplotlib/core.py", line 1577, in _post_plot_logic
    s_edge = self.ax_pos[0] - 0.25 + self.lim_offset
IndexError: index 0 is out of bounds for axis 0 with size 0
